INFO     WDM:logger.py:22 

INFO     WDM:logger.py:12 ====== WebDriver manager ======
INFO     WDM:logger.py:12 Current google-chrome version is 92.0.4515
INFO     WDM:logger.py:12 Get LATEST driver version for 92.0.4515
INFO     WDM:logger.py:12 There is no [linux64] chromedriver for browser 92.0.4515 in cache
INFO     WDM:logger.py:12 Get LATEST driver version for 92.0.4515
INFO     WDM:logger.py:12 Trying to download new driver from https://chromedriver.storage.googleapis.com/92.0.4515.107/chromedriver_linux64.zip
INFO     WDM:logger.py:12 Driver has been saved in cache [/home/runner/.wdm/drivers/chromedriver/linux64/92.0.4515.107]
WARNING  urllib3.connectionpool:connectionpool.py:780 Retrying (Retry(total=2, connect=None, read=None, redirect=None, status=None)) after connection broken by 'NewConnectionError('<urllib3.connection.HTTPConnection object at 0x7fe527622340>: Failed to establish a new connection: [Errno 111] Connection refused')': /session/071a8f49235fc4009657e5447e0d1fc7
WARNING  urllib3.connectionpool:connectionpool.py:780 Retrying (Retry(total=1, connect=None, read=None, redirect=None, status=None)) after connection broken by 'NewConnectionError('<urllib3.connection.HTTPConnection object at 0x7fe527622790>: Failed to establish a new connection: [Errno 111] Connection refused')': /session/071a8f49235fc4009657e5447e0d1fc7
WARNING  urllib3.connectionpool:connectionpool.py:780 Retrying (Retry(total=0, connect=None, read=None, redirect=None, status=None)) after connection broken by 'NewConnectionError('<urllib3.connection.HTTPConnection object at 0x7fe52761fb50>: Failed to establish a new connection: [Errno 111] Connection refused')': /session/071a8f49235fc4009657e5447e0d1fc7